# 2023-06-27 화요일 13:30 - 

### Promise Chaning (then, catch에서 return)

```js
const x = new Promise((resolve, reject) => {
    setTimeout(() => {
        resolve('첫번째 프라미스')
    }, 1000)
}).then(res => {
    console.log(res)                                    // '첫번째 프라미스'
    return '두번째 프라미스'
}).then(res => {
    console.log(res)                                    // '두번째 프라미스'
    return new Promise((resolve, reject) => {
        setTimeout(() => {
            resolve('세번째 프라미스')
        }, 1000)
    })
}).then(res => {
    console.log(res)                                    // '세번째 프라미스'
    return new Promise((resolve, reject) => {
        setTimeout(() => {
            reject('네번째 프라미스')
        }, 1000)
    })
}).then(res => {
    console.log(res)                                    // pass
}).catch(err => {
    console.error(err)                                  // error - '네번째 프라미스'
    return new Error('이 에러는 then에 잡힙니다.')
}).then(res => {
    console.log(res)                                    // '이 에러는 then에 잡힙니다.'
    throw new Error('이 에러는 catch에 잡힙니다.')
}).then(res => {
    console.log('출력 안됨')                            // pass
}).catch(err => {
    console.error(err)                                  // '이 에러는 catch에 잡힙니다.'
})

/*
.then 이나 .catch 안에서
1. return promise 인스턴스 : promise 인스턴스가 리턴된 것. // return new Promise() or return Promise.resolve()
2 return 일반값 : promise 객체에 resolved 상태로 반환됨. 그 안에 값이 담김 // Promise { << resolved >> : 값 }
3. return 안하면 : return undefined (원래 js 동작이 이러함) -> 2번과 같다.
4. Promise.resolve() or Promise.reject() : return 해주지 않는 이상 의미없음.
    // 별개의 프라미스 객체가 생성될 뿐, 현재 process 상의 Promise 플로우에 영향을 주지 않음
    // return 한거는 1번과 같음.

.then(() => {})
.then(() => {})
*/

x.then(res => { console.log(1) }) // 계속 가능
```

### Error Handling

```js
// 실행 X
asyncThing1()
.then(asyncThing2)
.then(asyncThing3)
.catch(asyncRecovery1)
.then(asyncThing4, asyncRecovery2)
.catch(err => { console.log("Don't worry about it") })
.then(() => { console.log("All done!") })

/*
asyncThing1             ㄱ
    ⬇                    ⬇
asyncThing2        ㄱ    ⬇
    ⬇               ⬇    ⬇
asyncThing3  ➡  asyncRecovery1
    ⬇        ↙     ⬇
asyncThing4      asyncRecovery2        ㄱ
    ⬇       ↘      ⬇                   ⬇
    ⬇          "Don't Worry about it!"  ⬇
"All Done!" ↙                         ⬅ 
*/
// https://gomugom.github.io
```

![에러 핸들링](https://raw.githubusercontent.com/js-jsm/es6js/master/15%20%ED%94%84%EB%9D%BC%EB%AF%B8%EC%8A%A4/promise_chaining.png)

### Multi Handling

#### 1. `Promise.all()`

- iterable의 모든 요소가 fulfilled되는 경우: 전체 결과값들을 배열 형태로 then에 전달.
- iterable의 요소 중 일부가 rejected되는 경우: 가장 먼저 rejected 되는 요소 '하나'의 결과를 catch에 전달.

```js
const arr = [
	1,
	new Promise((resolve, reject) => {
		setTimeout(()=> {
			resolve('resolved after 1000ms')
		}, 1000)
	}),
	'abc',
	() => 'not called function',
	(() => 'IIFE')()
]

Promise.all(arr)
.then(res => { console.log(res) })
.catch(err => { console.error(err) })
```

```js
const arr = [
	1,
	new Promise((resolve, reject) => {
		setTimeout(()=> {
			reject('rejected after 1000ms')
		}, 1000)
	}),
	'abc',
	()=> 'not called function',
	(()=> 'IIFE')()
]

Promise.all(arr)
.then(res => { console.log(res) })
.catch(err => { console.error(err) })

/* 
Promise.all(iterable) : Array.prototye.every() 와 비슷한 느낌
1. 일반 값은 그냥 resolved 된 값으로 간주.
2. iterable 내의 모든 요소들이 resolved 된 순간에 다음번 then 호출. 이 때 값은 iterable 실행 결과가 배열로 반환 됨.
3. iterable 내의 일부 요소가, 하나라도 reject 되면, 그 순간에 catch 를 호출하며 reject 된 값만 넘어온다.
*/
```

#### 2. `Promise.race()`

- iterable의 요소 중 가장 먼저 fulfilled / rejected되는 요소의 결과를 then / catch에 전달.

```js
const arr = [
	new Promise(resolve => {
		setTimeout(()=> { resolve('1번요소, 1000ms') }, 1000)
	}),
	new Promise(resolve => {
		setTimeout(()=> { resolve('2번요소, 500ms') }, 500)
	}),
	new Promise(resolve => {
		setTimeout(()=> { resolve('3번요소, 750ms') }, 750)
	})
]
Promise.race(arr)
.then(res => { console.log(res) })
.catch(err => { console.error(err) })

/* 
Promise.all(iterable) : Array.prototye.some() 과 비슷한 느낌
1. 일반 값은 그냥 resolved 된 값으로 간주.
2. iterable 내의 모든 요소 중에 가장 먼저 resolved (then) 또는 reject (catch) 된 값을 반환 함.
*/
```

```js
const arr = [
	new Promise(resolve => {
		setTimeout(()=> { resolve('1번요소, 0ms') }, 0)
	}),
	'no queue'
]
Promise.race(arr)
.then(res => { console.log(res) })
.catch(err => { console.error(err) })

/*
Promise.all      : All / or / one error
Promise.race     : only the fastest one
*/
```

> 참고: [ES2017 Async Function](https://developer.mozilla.org/ko/docs/Web/JavaScript/Reference/Statements/async_function)

```js
function resolveAfter2Seconds() {
    return new Promise(resolve => {
        setTimeout(() => {
            resolve('resolved');
        }, 2000);
    });
}

async function asyncCall() {
    console.log('calling');
    const result = await resolveAfter2Seconds();
    console.log(result);
    // Expected output: "resolved"
}

asyncCall();
```

### Proxy & Reflection